Workbook

Sheet Plan1
B2: STATUS GERAL
B3: PEDIDO | C3: VENDEDOR | D3: CODIGO | E3: DATA | F3: DIVERGENCIA | G3: CLIENTE
B4: 195474 | C4: MARTA | D4: 67493 | E4: 46129 | F4: ZERAR ESTOQUE | G4: =_xlfn.XLOOKUP(Tabela1[[#This Row],[PEDIDO]],'BASE_5 2 3 B'!AB:AB,'BASE_5 2 3 B'!I:I) -> METALMUNDI IND.COM.SER.LTDA
B5: 195485 | C5: ANA | D5: 58078 | E5: 46129 | F5: FISICO 81 | G5: =_xlfn.XLOOKUP(Tabela1[[#This Row],[PEDIDO]],'BASE_5 2 3 B'!AB:AB,'BASE_5 2 3 B'!I:I) -> #N/A
B6: 195497 | C6: ANA | D6: 4422 | E6: 46132 | F6: ZERAR ESTOQUE | G6: =_xlfn.XLOOKUP(Tabela1[[#This Row],[PEDIDO]],'BASE_5 2 3 B'!AB:AB,'BASE_5 2 3 B'!I:I) -> MINERACAO VERA CRUZ LTDA
B7: 195457 | C7: ANA | D7: 47656 | E7: 46132 | F7: ZERAR ESTOQUE | G7: =_xlfn.XLOOKUP(Tabela1[[#This Row],[PEDIDO]],'BASE_5 2 3 B'!AB:AB,'BASE_5 2 3 B'!I:I) -> NAT CEREAIS E ALIMENTOS LTDA.
B8: 195520 | C8: JOSÉ | D8: 48579 | E8: 46132 | F8: ZERAR ESTOQUE | G8: =_xlfn.XLOOKUP(Tabela1[[#This Row],[PEDIDO]],'BASE_5 2 3 B'!AB:AB,'BASE_5 2 3 B'!I:I) -> MADEIREIRA GIGANTE LTDA
B9: 195566 | C9: ANA | D9: 56862 | E9: 46134 | F9: fisico 223 | G9: =_xlfn.XLOOKUP(Tabela1[[#This Row],[PEDIDO]],'BASE_5 2 3 B'!AB:AB,'BASE_5 2 3 B'!I:I) -> #N/A
B10: 195625 | C10: WILIAM | D10: 51697 | E10: 46134 | F10: ZERAR ESTOQUE | G10: =_xlfn.XLOOKUP(Tabela1[[#This Row],[PEDIDO]],'BASE_5 2 3 B'!AB:AB,'BASE_5 2 3 B'!I:I) -> #N/A
B11: 195714 | C11: RENAN | D11: 65377 | E11: 46134 | F11: ZERAR ESTOQUE | G11: =_xlfn.XLOOKUP(Tabela1[[#This Row],[PEDIDO]],'BASE_5 2 3 B'!AB:AB,'BASE_5 2 3 B'!I:I) -> #N/A
B12: 195720 | C12: ANA | D12: 5633 | E12: 46135 | F12: ZERAR ESTOQUE | G12: =_xlfn.XLOOKUP(Tabela1[[#This Row],[PEDIDO]],'BASE_5 2 3 B'!AB:AB,'BASE_5 2 3 B'!I:I) -> #N/A
B13: 195784 | C13: ANA | D13: 68683 | E13: 46135 | F13: ZERAR ESTOQUE | G13: =_xlfn.XLOOKUP(Tabela1[[#This Row],[PEDIDO]],'BASE_5 2 3 B'!AB:AB,'BASE_5 2 3 B'!I:I) -> #N/A
B14: 195687 | C14: PATRICIA | D14: 54537 | E14: 46135 | F14: ZERAR ESTOQUE | G14: =_xlfn.XLOOKUP(Tabela1[[#This Row],[PEDIDO]],'BASE_5 2 3 B'!AB:AB,'BASE_5 2 3 B'!I:I) -> #N/A
B15: 195815 | C15: ANA | D15: 47874 | E15: 46135 | F15: ZERAR ESTOQUE | G15: =_xlfn.XLOOKUP(Tabela1[[#This Row],[PEDIDO]],'BASE_5 2 3 B'!AB:AB,'BASE_5 2 3 B'!I:I) -> #N/A
... B32: 193122 | C32: TIAGO | D32: 50644 | E32: 46139 | F32: ZERAR ESTOQUE | G32: =_xlfn.XLOOKUP(Tabela1[[#This Row],[PEDIDO]],'BASE_5 2 3 B'!AB:AB,'BASE_5 2 3 B'!I:I) -> SCS IND.COM.DE EMBARCACOES LTD

Sheet BASE_5 2 3 B
A1: Nome da Origem | B1: Column1 | C1: Série | D1: Nota | E1: Posição detalhada | F1: CFOP | G1: CFOP_1 | H1: Cli/for | I1: Razão social | J1: Cidade | K1: UF | L1: Dt.fatur | M1: Vlr.nota | N1: Fatura | O1: ID nota | P1: Situação da NF-e | Q1: Pedido | R1: Cubagem volumes | S1: Peso bruto volume | T1: Qtd.volume | U1: Via tran | V1: Abreviação | W1: Código | X1: Peso líq.volume | Y1: Obs.comerc | Z1: Desc.repr/prep | AA1: Column26 | AB1: PEDIDO NUMERO
A2: SIGER_XLS_944116_260326_100411.xlsx | E2: P/faturar | F2: 5405 | H2: 100 | I2: VENDAS A CONSUMIDOR | J2: PORTO ALEGRE | K2: RS-Rio Grande do Sul | L2: 46028 | M2: 54.15 | O2: 242135 | Q2: Cód: 0 | U2: 1-Rodoviário | V2: DESTINATÁRIO | W2: 2 | Z2: RAEL | AB2: =VALUE(SUBSTITUTE(BASE_5_2_3_B[[#This Row],[Pedido]],"Cód: ","")) -> 0
A3: SIGER_XLS_944116_260326_100411.xlsx | E3: P/faturar | F3: 5405 | H3: 100 | I3: VENDAS A CONSUMIDOR | J3: PORTO ALEGRE | K3: RS-Rio Grande do Sul | L3: 46030 | M3: 5.1 | O3: 242503 | Q3: Cód: 0 | U3: 1-Rodoviário | V3: DESTINATÁRIO | W3: 2 | Z3: RAEL | AB3: =VALUE(SUBSTITUTE(BASE_5_2_3_B[[#This Row],[Pedido]],"Cód: ","")) -> 0
A4: SIGER_XLS_944116_260326_100411.xlsx | E4: Cancelada | F4: 5405 | H4: 100 | I4: VENDAS A CONSUMIDOR | J4: PORTO ALEGRE | K4: RS-Rio Grande do Sul | L4: 46031 | M4: 40.63 | O4: 242630 | Q4: Cód: 0 | U4: 1-Rodoviário | Z4: ALEX | AB4: =VALUE(SUBSTITUTE(BASE_5_2_3_B[[#This Row],[Pedido]],"Cód: ","")) -> 0
A5: SIGER_XLS_944116_260326_100411.xlsx | E5: Cancelada | F5: 5405 | H5: 100 | I5: VENDAS A CONSUMIDOR | J5: PORTO ALEGRE | K5: RS-Rio Grande do Sul | L5: 46031 | M5: 40.63 | O5: 242631 | Q5: Cód: 0 | U5: 1-Rodoviário | Z5: ALEX | AB5: =VALUE(SUBSTITUTE(BASE_5_2_3_B[[#This Row],[Pedido]],"Cód: ","")) -> 0
A6: SIGER_XLS_944116_260326_100411.xlsx | E6: Cancelada | F6: 6108 | H6: 15719 | I6: KMV ENGENHAR.DE EQUIP.INDS.LTD | J6: DIADEMA | K6: SP-São Paulo | L6: 46031 | M6: 1471.82 | O6: 242692 | P6: NF-e rejeitada | Q6: Cód: 184955 | T6: 2 | U6: 1-Rodoviário | V6: DESTINATÁRIO | W6: 2 | Y6: JENNIFER | Z6: ANA | AB6: =VALUE(SUBSTITUTE(BASE_5_2_3_B[[#This Row],[Pedido]],"Cód: ","")) -> 184955
A7: SIGER_XLS_944116_260326_100411.xlsx | E7: Cancelada | F7: 6108 | H7: 15724 | I7: JB NOROESTE TRANSPORTES LTDA. | J7: BAURU | K7: SP-São Paulo | L7: 46034 | M7: 527.65 | O7: 242791 | P7: NF-e rejeitada | Q7: Cód: 185109 | T7: 1 | U7: 1-Rodoviário | V7: RÉGIS | W7: 4 | Y7: ALISSON | Z7: ANA | AB7: =VALUE(SUBSTITUTE(BASE_5_2_3_B[[#This Row],[Pedido]],"Cód: ","")) -> 185109
A8: SIGER_XLS_944116_260326_100411.xlsx | E8: Cancelada | F8: 1411 | H8: 15741 | I8: FERNANDO DA SILVA PINTO | J8: PORTO ALEGRE | K8: RS-Rio Grande do Sul | L8: 46035 | M8: 149.29 | O8: 242997 | P8: NF-e rejeitada | Q8: Cód: 0 | U8: 1-Rodoviário | V8: EMITENTE | W8: 1 | AB8: =VALUE(SUBSTITUTE(BASE_5_2_3_B[[#This Row],[Pedido]],"Cód: ","")) -> 0
A9: SIGER_XLS_944116_260326_100411.xlsx | E9: Cancelada | F9: 1411 | H9: 15741 | I9: FERNANDO DA SILVA PINTO | J9: PORTO ALEGRE | K9: RS-Rio Grande do Sul | L9: 46035 | M9: 149.29 | O9: 243000 | P9: NF-e rejeitada | Q9: Cód: 0 | U9: 1-Rodoviário | V9: EMITENTE | W9: 1 | AB9: =VALUE(SUBSTITUTE(BASE_5_2_3_B[[#This Row],[Pedido]],"Cód: ","")) -> 0
A10: SIGER_XLS_944116_260326_100411.xlsx | E10: P/faturar | F10: 5405 | H10: 100 | I10: VENDAS A CONSUMIDOR | J10: PORTO ALEGRE | K10: RS-Rio Grande do Sul | L10: 46036 | M10: 849.2 | O10: 243173 | Q10: Cód: 0 | U10: 1-Rodoviário | V10: DESTINATÁRIO | W10: 2 | Z10: RAEL | AB10: =VALUE(SUBSTITUTE(BASE_5_2_3_B[[#This Row],[Pedido]],"Cód: ","")) -> 0
A11: SIGER_XLS_944116_260326_100411.xlsx | E11: Cancelada | F11: 5405 | H11: 100 | I11: VENDAS A CONSUMIDOR | J11: PORTO ALEGRE | K11: RS-Rio Grande do Sul | L11: 46037 | M11: 18.38 | O11: 243341 | Q11: Cód: 0 | U11: 1-Rodoviário | Z11: PATRICIA | AB11: =VALUE(SUBSTITUTE(BASE_5_2_3_B[[#This Row],[Pedido]],"Cód: ","")) -> 0
A12: SIGER_XLS_944116_260326_100411.xlsx | E12: P/faturar | F12: 5405 | H12: 100 | I12: VENDAS A CONSUMIDOR | J12: PORTO ALEGRE | K12: RS-Rio Grande do Sul | L12: 46038 | M12: 519.16 | O12: 243492 | Q12: Cód: 0 | U12: 1-Rodoviário | V12: DESTINATÁRIO | W12: 2 | Z12: RAEL | AB12: =VALUE(SUBSTITUTE(BASE_5_2_3_B[[#This Row],[Pedido]],"Cód: ","")) -> 0
A13: SIGER_XLS_944116_260326_100411.xlsx | E13: P/faturar (Separada) | F13: 5405 | H13: 6093 | I13: LAZZARI IND.COM.MOBILIARIO URBAN | J13: PORTO ALEGRE | K13: RS-Rio Grande do Sul | L13: 46042 | M13: 24.56 | O13: 243945 | Q13: Cód: 186224 | T13: 1 | U13: 1-Rodoviário | V13: DESTINATÁRIO | W13: 2 | Y13: DANIIIIIIIIIIIIIIIIII | Z13: MARTA | AB13: =VALUE(SUBSTITUTE(BASE_5_2_3_B[[#This Row],[Pedido]],"Cód: ","")) -> 186224
A14: SIGER_XLS_944116_260326_100411.xlsx | E14: Cancelada | F14: 6108 | H14: 15792 | I14: VISTA SEMPRE ALEM LTDA | J14: SAO PAULO | K14: SP-São Paulo | L14: 46048 | M14: 75.9 | O14: 244527 | P14: NF-e rejeitada | Q14: Cód: 186754 | U14: 1-Rodoviário | V14: DESTINATÁRIO | W14: 2 | Z14: RAEL | AB14: =VALUE(SUBSTITUTE(BASE_5_2_3_B[[#This Row],[Pedido]],"Cód: ","")) -> 186754
A15: SIGER_XLS_944116_260326_100411.xlsx | E15: P/faturar (Separada) | F15: 5405 | H15: 7682 | I15: FÁB.DE EMBUTIDOS BORRUSSIA LTDA | J15: OSORIO | K15: RS-Rio Grande do Sul | L15: 46049 | M15: 40.92 | O15: 249368 | Q15: Cód: 186887 | T15: 1 | U15: 1-Rodoviário | V15: SAO MIGUEL | W15: 6 | Y15: EVERTON | Z15: ANA | AB15: =VALUE(SUBSTITUTE(BASE_5_2_3_B[[#This Row],[Pedido]],"Cód: ","")) -> 186887
A16: SIGER_XLS_944116_260326_100411.xlsx | C16: 8 | D16: 93 | E16: Faturada | F16: 5405 | H16: 100 | I16: VENDAS A CONSUMIDOR | J16: PORTO ALEGRE | K16: RS-Rio Grande do Sul | L16: 46028 | M16: 34.72 | O16: 242024 | P16: NFC-e enviada | Q16: Cód: 0 | U16: 1-Rodoviário | Z16: PATRICIA | AB16: =VALUE(SUBSTITUTE(BASE_5_2_3_B[[#This Row],[Pedido]],"Cód: ","")) -> 0
A17: SIGER_XLS_944116_260326_100411.xlsx | C17: 8 | D17: 94 | E17: Faturada | F17: 5405 | H17: 100 | I17: VENDAS A CONSUMIDOR | J17: PORTO ALEGRE | K17: RS-Rio Grande do Sul | L17: 46028 | M17: 75.52 | O17: 242025 | P17: NFC-e enviada | Q17: Cód: 0 | U17: 1-Rodoviário | Z17: PATRICIA | AB17: =VALUE(SUBSTITUTE(BASE_5_2_3_B[[#This Row],[Pedido]],"Cód: ","")) -> 0
A18: SIGER_XLS_944116_260326_100411.xlsx | C18: 8 | D18: 95 | E18: Faturada | F18: 5405 | H18: 100 | I18: VENDAS A CONSUMIDOR | J18: PORTO ALEGRE | K18: RS-Rio Grande do Sul | L18: 46028 | M18: 9.14 | O18: 242054 | P18: NFC-e enviada | Q18: Cód: 0 | U18: 1-Rodoviário | Z18: PATRICIA | AB18: =VALUE(SUBSTITUTE(BASE_5_2_3_B[[#This Row],[Pedido]],"Cód: ","")) -> 0
A19: SIGER_XLS_944116_260326_100411.xlsx | C19: 8 | D19: 96 | E19: Faturada | F19: 5102 | G19: 5405 | H19: 100 | I19: VENDAS A CONSUMIDOR | J19: PORTO ALEGRE | K19: RS-Rio Grande do Sul | L19: 46028 | M19: 10.87 | O19: 242057 | P19: NFC-e enviada | Q19: Cód: 0 | U19: 1-Rodoviário | Z19: PATRICIA | AB19: =VALUE(SUBSTITUTE(BASE_5_2_3_B[[#This Row],[Pedido]],"Cód: ","")) -> 0
A20: SIGER_XLS_944116_260326_100411.xlsx | C20: 8 | D20: 97 | E20: Faturada | F20: 5405 | H20: 100 | I20: VENDAS A CONSUMIDOR | J20: PORTO ALEGRE | K20: RS-Rio Grande do Sul | L20: 46028 | M20: 6.95 | O20: 242064 | P20: NFC-e enviada | Q20: Cód: 0 | U20: 1-Rodoviário | Z20: PATRICIA | AB20: =VALUE(SUBSTITUTE(BASE_5_2_3_B[[#This Row],[Pedido]],"Cód: ","")) -> 0
A21: SIGER_XLS_944116_260326_100411.xlsx | C21: 8 | D21: 98 | E21: Faturada | F21: 5405 | H21: 100 | I21: VENDAS A CONSUMIDOR | J21: PORTO ALEGRE | K21: RS-Rio Grande do Sul | L21: 46028 | M21: 14.78 | O21: 242067 | P21: NFC-e enviada | Q21: Cód: 0 | U21: 1-Rodoviário | Z21: PATRICIA | AB21: =VALUE(SUBSTITUTE(BASE_5_2_3_B[[#This Row],[Pedido]],"Cód: ","")) -> 0
A22: SIGER_XLS_944116_260326_100411.xlsx | C22: 8 | D22: 99 | E22: Faturada | F22: 5405 | H22: 100 | I22: VENDAS A CONSUMIDOR | J22: PORTO ALEGRE | K22: RS-Rio Grande do Sul | L22: 46028 | M22: 33.88 | O22: 242076 | P22: NFC-e enviada | Q22: Cód: 0 | U22: 1-Rodoviário | Z22: PATRICIA | AB22: =VALUE(SUBSTITUTE(BASE_5_2_3_B[[#This Row],[Pedido]],"Cód: ","")) -> 0
A23: SIGER_XLS_944116_260326_100411.xlsx | C23: 8 | D23: 100 | E23: Faturada | F23: 5405 | H23: 100 | I23: VENDAS A CONSUMIDOR | J23: PORTO ALEGRE | K23: RS-Rio Grande do Sul | L23: 46028 | M23: 88.41 | O23: 242079 | P23: NFC-e enviada | Q23: Cód: 0 | U23: 1-Rodoviário | Z23: RAEL | AB23: =VALUE(SUBSTITUTE(BASE_5_2_3_B[[#This Row],[Pedido]],"Cód: ","")) -> 0
A24: SIGER_XLS_944116_260326_100411.xlsx | C24: 8 | D24: 101 | E24: Faturada | F24: 5405 | H24: 100 | I24: VENDAS A CONSUMIDOR | J24: PORTO ALEGRE | K24: RS-Rio Grande do Sul | L24: 46028 | M24: 37.4 | O24: 242083 | P24: NFC-e enviada | Q24: Cód: 0 | U24: 1-Rodoviário | Z24: PATRICIA | AB24: =VALUE(SUBSTITUTE(BASE_5_2_3_B[[#This Row],[Pedido]],"Cód: ","")) -> 0
A25: SIGER_XLS_944116_260326_100411.xlsx | C25: 8 | D25: 102 | E25: Faturada | F25: 5405 | H25: 100 | I25: VENDAS A CONSUMIDOR | J25: PORTO ALEGRE | K25: RS-Rio Grande do Sul | L25: 46028 | M25: 57.66 | O25: 242089 | P25: NFC-e enviada | Q25: Cód: 0 | U25: 1-Rodoviário | Z25: PATRICIA | AB25: =VALUE(SUBSTITUTE(BASE_5_2_3_B[[#This Row],[Pedido]],"Cód: ","")) -> 0
A26: SIGER_XLS_944116_260326_100411.xlsx | C26: 8 | D26: 103 | E26: Faturada | F26: 5102 | H26: 11771 | I26: PAULO KAWAN | J26: PORTO ALEGRE | K26: RS-Rio Grande do Sul | L26: 46028 | M26: 29.03 | O26: 242093 | P26: NFC-e enviada | Q26: Cód: 0 | U26: 1-Rodoviário | Z26: PATRICIA | AB26: =VALUE(SUBSTITUTE(BASE_5_2_3_B[[#This Row],[Pedido]],"Cód: ","")) -> 0
A27: SIGER_XLS_944116_260326_100411.xlsx | C27: 8 | D27: 104 | E27: Faturada | F27: 5102 | H27: 100 | I27: VENDAS A CONSUMIDOR | J27: PORTO ALEGRE | K27: RS-Rio Grande do Sul | L27: 46028 | M27: 127.3 | O27: 242121 | P27: NFC-e enviada | Q27: Cód: 0 | U27: 1-Rodoviário | Z27: PATRICIA | AB27: =VALUE(SUBSTITUTE(BASE_5_2_3_B[[#This Row],[Pedido]],"Cód: ","")) -> 0
A28: SIGER_XLS_944116_260326_100411.xlsx | C28: 8 | D28: 105 | E28: Faturada | F28: 5405 | H28: 100 | I28: VENDAS A CONSUMIDOR | J28: PORTO ALEGRE | K28: RS-Rio Grande do Sul | L28: 46028 | M28: 5.01 | O28: 242138 | P28: NFC-e enviada | Q28: Cód: 0 | U28: 1-Rodoviário | Z28: PATRICIA | AB28: =VALUE(SUBSTITUTE(BASE_5_2_3_B[[#This Row],[Pedido]],"Cód: ","")) -> 0
A29: SIGER_XLS_944116_260326_100411.xlsx | C29: 8 | D29: 106 | E29: Faturada | F29: 5405 | H29: 100 | I29: VENDAS A CONSUMIDOR | J29: PORTO ALEGRE | K29: RS-Rio Grande do Sul | L29: 46028 | M29: 29.48 | O29: 242161 | P29: NFC-e enviada | Q29: Cód: 0 | U29: 1-Rodoviário | Z29: PATRICIA | AB29: =VALUE(SUBSTITUTE(BASE_5_2_3_B[[#This Row],[Pedido]],"Cód: ","")) -> 0
A30: SIGER_XLS_944116_260326_100411.xlsx | C30: 8 | D30: 107 | E30: Faturada | F30: 5102 | G30: 5405 | H30: 100 | I30: VENDAS A CONSUMIDOR | J30: PORTO ALEGRE | K30: RS-Rio Grande do Sul | L30: 46028 | M30: 279.89 | O30: 242163 | P30: NFC-e enviada | Q30: Cód: 0 | U30: 1-Rodoviário | Z30: PATRICIA | AB30: =VALUE(SUBSTITUTE(BASE_5_2_3_B[[#This Row],[Pedido]],"Cód: ","")) -> 0
A31: SIGER_XLS_944116_260326_100411.xlsx | C31: 8 | D31: 108 | E31: Faturada | F31: 5405 | H31: 100 | I31: VENDAS A CONSUMIDOR | J31: PORTO ALEGRE | K31: RS-Rio Grande do Sul | L31: 46028 | M31: 46.46 | O31: 242171 | P31: NFC-e enviada | Q31: Cód: 0 | U31: 1-Rodoviário | Z31: PATRICIA | AB31: =VALUE(SUBSTITUTE(BASE_5_2_3_B[[#This Row],[Pedido]],"Cód: ","")) -> 0
A32: SIGER_XLS_944116_260326_100411.xlsx | C32: 8 | D32: 109 | E32: Cancelada | F32: 5405 | H32: 100 | I32: VENDAS A CONSUMIDOR | J32: PORTO ALEGRE | K32: RS-Rio Grande do Sul | L32: 46028 | M32: 5 | O32: 242175 | P32: NFC-e cancelada | Q32: Cód: 0 | U32: 1-Rodoviário | Z32: PATRICIA | AB32: =VALUE(SUBSTITUTE(BASE_5_2_3_B[[#This Row],[Pedido]],"Cód: ","")) -> 0
A33: SIGER_XLS_944116_260326_100411.xlsx | C33: 8 | D33: 110 | E33: Faturada | F33: 5405 | H33: 100 | I33: VENDAS A CONSUMIDOR | J33: PORTO ALEGRE | K33: RS-Rio Grande do Sul | L33: 46028 | M33: 5 | O33: 242176 | P33: NFC-e enviada | Q33: Cód: 0 | U33: 1-Rodoviário | Z33: PATRICIA | AB33: =VALUE(SUBSTITUTE(BASE_5_2_3_B[[#This Row],[Pedido]],"Cód: ","")) -> 0
A34: SIGER_XLS_944116_260326_100411.xlsx | C34: 8 | D34: 111 | E34: Faturada | F34: 5405 | H34: 100 | I34: VENDAS A CONSUMIDOR | J34: PORTO ALEGRE | K34: RS-Rio Grande do Sul | L34: 46028 | M34: 5.77 | O34: 242189 | P34: NFC-e enviada | Q34: Cód: 0 | U34: 1-Rodoviário | Z34: PATRICIA | AB34: =VALUE(SUBSTITUTE(BASE_5_2_3_B[[#This Row],[Pedido]],"Cód: ","")) -> 0
A35: SIGER_XLS_944116_260326_100411.xlsx | C35: 8 | D35: 112 | E35: Faturada | F35: 5405 | H35: 100 | I35: VENDAS A CONSUMIDOR | J35: PORTO ALEGRE | K35: RS-Rio Grande do Sul | L35: 46029 | M35: 243.08 | O35: 242210 | P35: NFC-e enviada | Q35: Cód: 0 | U35: 1-Rodoviário | Z35: PATRICIA | AB35: =VALUE(SUBSTITUTE(BASE_5_2_3_B[[#This Row],[Pedido]],"Cód: ","")) -> 0
A36: SIGER_XLS_944116_260326_100411.xlsx | C36: 8 | D36: 113 | E36: Faturada | F36: 5102 | G36: 5405 | H36: 100 | I36: VENDAS A CONSUMIDOR | J36: PORTO ALEGRE | K36: RS-Rio Grande do Sul | L36: 46029 | M36: 36.66 | O36: 242219 | P36: NFC-e enviada | Q36: Cód: 0 | U36: 1-Rodoviário | Z36: PATRICIA | AB36: =VALUE(SUBSTITUTE(BASE_5_2_3_B[[#This Row],[Pedido]],"Cód: ","")) -> 0
A37: SIGER_XLS_944116_260326_100411.xlsx | C37: 8 | D37: 114 | E37: Faturada | F37: 5405 | H37: 100 | I37: VENDAS A CONSUMIDOR | J37: PORTO ALEGRE | K37: RS-Rio Grande do Sul | L37: 46029 | M37: 5.16 | O37: 242223 | P37: NFC-e enviada | Q37: Cód: 0 | U37: 1-Rodoviário | Z37: PATRICIA | AB37: =VALUE(SUBSTITUTE(BASE_5_2_3_B[[#This Row],[Pedido]],"Cód: ","")) -> 0
A38: SIGER_XLS_944116_260326_100411.xlsx | C38: 8 | D38: 115 | E38: Faturada | F38: 5102 | G38: 5405 | H38: 100 | I38: VENDAS A CONSUMIDOR | J38: PORTO ALEGRE | K38: RS-Rio Grande do Sul | L38: 46029 | M38: 60.62 | O38: 242237 | P38: NFC-e enviada | Q38: Cód: 0 | U38: 1-Rodoviário | Z38: PATRICIA | AB38: =VALUE(SUBSTITUTE(BASE_5_2_3_B[[#This Row],[Pedido]],"Cód: ","")) -> 0
A39: SIGER_XLS_944116_260326_100411.xlsx | C39: 8 | D39: 116 | E39: Faturada | F39: 5405 | H39: 100 | I39: VENDAS A CONSUMIDOR | J39: PORTO ALEGRE | K39: RS-Rio Grande do Sul | L39: 46029 | M39: 5 | O39: 242241 | P39: NFC-e enviada | Q39: Cód: 0 | U39: 1-Rodoviário | Z39: PATRICIA | AB39: =VALUE(SUBSTITUTE(BASE_5_2_3_B[[#This Row],[Pedido]],"Cód: ","")) -> 0
A40: SIGER_XLS_944116_260326_100411.xlsx | C40: 8 | D40: 117 | E40: Faturada | F40: 5102 | G40: 5405 | H40: 100 | I40: VENDAS A CONSUMIDOR | J40: PORTO ALEGRE | K40: RS-Rio Grande do Sul | L40: 46029 | M40: 82.97 | O40: 242242 | P40: NFC-e enviada | Q40: Cód: 0 | U40: 1-Rodoviário | Z40: PATRICIA | AB40: =VALUE(SUBSTITUTE(BASE_5_2_3_B[[#This Row],[Pedido]],"Cód: ","")) -> 0
...
